<sdf version='1.10'>
  <world name='no_more_prius'>
    <scene>
      <grid>false</grid>
      <ambient>0.400000006 0.400000006 0.400000006 1</ambient>
      <background>0.699999988 0.699999988 0.699999988 1</background>
      <shadows>true</shadows>
    </scene>
    <plugin name='ignition::gazebo::systems::Physics' filename='ignition-gazebo-physics-system'/>
    <plugin name='ignition::gazebo::systems::Sensors' filename='ignition-gazebo-sensors-system'>
      <render_engine>ogre2</render_engine>
    </plugin>
    <plugin name='ignition::gazebo::systems::UserCommands' filename='ignition-gazebo-user-commands-system'/>
    <plugin name='ignition::gazebo::systems::SceneBroadcaster' filename='ignition-gazebo-scene-broadcaster-system'/>
    <gui fullscreen='false'>
      <plugin name='3D View' filename='GzScene3D'>
        <ignition-gui>
          <title>3D View</title>
          <property type='bool' key='showTitleBar'>false</property>
          <property type='string' key='state'>docked</property>
        </ignition-gui>
        <engine>ogre2</engine>
        <scene>scene</scene>
        <ambient_light>0.4 0.4 0.4</ambient_light>
        <background_color>0.5 0.8 0.95</background_color>
        <camera_follow>
          <target>prius_hybrid</target>
          <p_gain>0.5</p_gain>
          <offset>0.5 5 2</offset>
        </camera_follow>
      </plugin>
      <plugin name='World control' filename='WorldControl'>
        <ignition-gui>
          <title>World control</title>
          <property type='bool' key='showTitleBar'>false</property>
          <property type='bool' key='resizable'>false</property>
          <property type='double' key='height'>72</property>
          <property type='double' key='width'>121</property>
          <property type='double' key='z'>1</property>
          <property type='string' key='state'>floating</property>
          <anchors target='3D View'>
            <line own='left' target='left'/>
            <line own='bottom' target='bottom'/>
          </anchors>
        </ignition-gui>
        <play_pause>true</play_pause>
        <step>true</step>
        <start_paused>true</start_paused>
      </plugin>
      <plugin name='World stats' filename='WorldStats'>
        <ignition-gui>
          <title>World stats</title>
          <property type='bool' key='showTitleBar'>false</property>
          <property type='bool' key='resizable'>false</property>
          <property type='double' key='height'>110</property>
          <property type='double' key='width'>290</property>
          <property type='double' key='z'>1</property>
          <property type='string' key='state'>floating</property>
          <anchors target='3D View'>
            <line own='right' target='right'/>
            <line own='bottom' target='bottom'/>
          </anchors>
        </ignition-gui>
        <sim_time>true</sim_time>
        <real_time>true</real_time>
        <real_time_factor>true</real_time_factor>
        <iterations>true</iterations>
      </plugin>
      <plugin name='dis' filename='ImageDisplay'>
        <ignition-gui>
          <property key='state' type='string'>docked</property>
        </ignition-gui>
        <topic>front_camera</topic>
      </plugin>
      <plugin name='Teleop' filename='Teleop'>
        <ignition-gui>
          <property type='string' key='state'>docked</property>
        </ignition-gui>
        <topic>/cmd_vel</topic>
      </plugin>
    </gui>
    <gravity>0 0 -9.8000000000000007</gravity>
    <magnetic_field>5.5644999999999998e-06 2.2875799999999999e-05 -4.2388400000000002e-05</magnetic_field>
    <atmosphere type='adiabatic'/>
    <physics type='ode'>
      <max_step_size>0.001</max_step_size>
      <real_time_factor>1</real_time_factor>
      <real_time_update_rate>1000</real_time_update_rate>
    </physics>
    <model name='sonoma_raceway'>
      <pose>0 0 -4.7999999999999998 0 0 0</pose>
      <static>true</static>
      <link name='link'>
        <collision name='collision'>
          <geometry>
            <mesh>
              <uri>https://fuel.ignitionrobotics.org/1.0/openrobotics/models/sonoma raceway/3/files/meshes/Raceway.obj</uri>
              <scale>0.025399999999999999 0.025399999999999999 0.025399999999999999</scale>
            </mesh>
          </geometry>
        </collision>
        <visual name='visual'>
          <geometry>
            <mesh>
              <uri>https://fuel.ignitionrobotics.org/1.0/openrobotics/models/sonoma raceway/3/files/meshes/Raceway.obj</uri>
              <scale>0.025399999999999999 0.025399999999999999 0.025399999999999999</scale>
            </mesh>
          </geometry>
        </visual>
        <pose>0 0 0 0 0 0</pose>
        <inertial>
          <pose>0 0 0 0 0 0</pose>
          <mass>1</mass>
          <inertia>
            <ixx>1</ixx>
            <ixy>0</ixy>
            <ixz>0</ixz>
            <iyy>1</iyy>
            <iyz>0</iyz>
            <izz>1</izz>
          </inertia>
        </inertial>
        <enable_wind>false</enable_wind>
      </link>
      <self_collide>false</self_collide>
    </model>
    <model name='prius_hybrid'>
      <pose>278.08006996121776 -134.22009419431532 2.8625642212351159 0.019786008417498988 -0.0021773718714598032 0.96995626609711305</pose>
      <link name='chassis'>
        <inertial>
          <mass>1326</mass>
          <pose>0 -0.26600000000000001 0.47999999999999998 0 0 0</pose>
          <inertia>
            <ixx>2581.1335474000002</ixx>
            <ixy>0</ixy>
            <iyy>591.30846111999995</iyy>
            <ixz>0</ixz>
            <iyz>0</iyz>
            <izz>2681.9500862800001</izz>
          </inertia>
        </inertial>
        <visual name='chassis_visual'>
          <geometry>
            <mesh>
              <uri>https://fuel.ignitionrobotics.org/1.0/openrobotics/models/prius hybrid/2/files/meshes/Hybrid.obj</uri>
              <scale>0.01 0.01 0.01</scale>
              <submesh>
                <name>Hybrid</name>
                <center>false</center>
              </submesh>
            </mesh>
          </geometry>
        </visual>
        <visual name='interior_visual'>
          <geometry>
            <mesh>
              <uri>https://fuel.ignitionrobotics.org/1.0/openrobotics/models/prius hybrid/2/files/meshes/Hybrid.obj</uri>
              <scale>0.01 0.01 0.01</scale>
              <submesh>
                <name>Hybrid_Interior</name>
                <center>false</center>
              </submesh>
            </mesh>
          </geometry>
        </visual>
        <visual name='windows_visual'>
          <geometry>
            <mesh>
              <uri>https://fuel.ignitionrobotics.org/1.0/openrobotics/models/prius hybrid/2/files/meshes/Hybrid.obj</uri>
              <scale>0.01 0.01 0.01</scale>
              <submesh>
                <name>Hybrid_Windows</name>
                <center>false</center>
              </submesh>
            </mesh>
          </geometry>
        </visual>
        <collision name='chassis'>
          <pose>0 0.050000000000000003 0.625 0 0 0</pose>
          <geometry>
            <box>
              <size>1.7525999999999999 2.1000000000000001 0.94999999999999996</size>
            </box>
          </geometry>
          <surface>
            <friction>
              <ode/>
            </friction>
            <bounce/>
            <contact/>
          </surface>
        </collision>
        <collision name='front_bumper'>
          <pose>0 -2 0.45848800000000001 0 0 0</pose>
          <geometry>
            <box>
              <size>1.3372820000000001 0.47999999999999998 0.56669099999999994</size>
            </box>
          </geometry>
          <surface>
            <friction>
              <ode/>
            </friction>
            <bounce/>
            <contact/>
          </surface>
        </collision>
        <collision name='hood'>
          <pose>0 -1.9008419999999999 0.67630500000000005 0.34124700000000019 0 0</pose>
          <geometry>
            <box>
              <size>1.5979680000000001 0.49310700000000002 0.26546799999999998</size>
            </box>
          </geometry>
          <surface>
            <friction>
              <ode/>
            </friction>
            <bounce/>
            <contact/>
          </surface>
        </collision>
        <collision name='windshield'>
          <pose>0 -0.87510500000000002 1.032268 0.335476 0 0</pose>
          <geometry>
            <box>
              <size>1.1683809999999999 1.654253 0.27234700000000001</size>
            </box>
          </geometry>
          <surface>
            <friction>
              <ode/>
            </friction>
            <bounce/>
            <contact/>
          </surface>
        </collision>
        <collision name='top_front'>
          <pose>0 0.16123599999999999 1.386042 0.13503000000000009 0 0</pose>
          <geometry>
            <box>
              <size>1.2791539999999999 0.62598799999999999 0.17186799999999999</size>
            </box>
          </geometry>
          <surface>
            <friction>
              <ode/>
            </friction>
            <bounce/>
            <contact/>
          </surface>
        </collision>
        <collision name='top_rear'>
          <pose>0 0.81769599999999998 1.360069 -0.068997000000000003 0 0</pose>
          <geometry>
            <box>
              <size>1.2851300000000001 0.77118900000000001 0.22655700000000001</size>
            </box>
          </geometry>
          <surface>
            <friction>
              <ode/>
            </friction>
            <bounce/>
            <contact/>
          </surface>
        </collision>
        <collision name='rear_window'>
          <pose>0 1.640531 1.1751259999999999 -0.26201699999999983 0 0</pose>
          <geometry>
            <box>
              <size>1.2678450000000001 1.116344 0.244286</size>
            </box>
          </geometry>
          <surface>
            <friction>
              <ode/>
            </friction>
            <bounce/>
            <contact/>
          </surface>
        </collision>
        <collision name='trunk'>
          <pose>0 1.637059 0.88817999999999997 0 0 0</pose>
          <geometry>
            <box>
              <size>1.7880640000000001 1.1389879999999999 0.48274600000000001</size>
            </box>
          </geometry>
          <surface>
            <friction>
              <ode/>
            </friction>
            <bounce/>
            <contact/>
          </surface>
        </collision>
        <collision name='back_bumper'>
          <pose>0 2.0544539999999998 0.57786999999999999 0 0 0</pose>
          <geometry>
            <box>
              <size>1.78165 0.51209300000000002 0.58142700000000003</size>
            </box>
          </geometry>
          <surface>
            <friction>
              <ode/>
            </friction>
            <bounce/>
            <contact/>
          </surface>
        </collision>
        <sensor name='back_camera_sensor' type='camera'>
          <pose>0 1.45 1.3999999999999999 0 0.050000000000000003 1.5707</pose>
          <topic>back_camera</topic>
          <update_rate>30</update_rate>
          <enable_metrics>false</enable_metrics>
          <camera>
            <pose>0 0 0 0 0 0</pose>
            <horizontal_fov>1.3962600000000001</horizontal_fov>
            <image>
              <width>800</width>
              <height>800</height>
              <format>RGB_INT8</format>
              <anti_aliasing>4</anti_aliasing>
            </image>
            <camera_info_topic>__default__</camera_info_topic>
            <trigger_topic></trigger_topic>
            <triggered>false</triggered>
            <clip>
              <near>0.02</near>
              <far>300</far>
            </clip>
            <save enabled='false'>
              <path>__default__</path>
            </save>
            <visibility_mask>4294967295</visibility_mask>
            <noise>
              <type>none</type>
              <mean>0</mean>
              <stddev>0</stddev>
            </noise>
            <distortion>
              <k1>0</k1>
              <k2>0</k2>
              <k3>0</k3>
              <p1>0</p1>
              <p2>0</p2>
              <center>0.5 0.5</center>
            </distortion>
            <lens>
              <type>stereographic</type>
              <scale_to_hfov>true</scale_to_hfov>
              <cutoff_angle>1.5707963267948966</cutoff_angle>
              <env_texture_size>256</env_texture_size>
            </lens>
            <optical_frame_id></optical_frame_id>
          </camera>
        </sensor>
        <sensor name='front_camera_sensor' type='camera'>
          <pose>0 -0.40000000000000002 1.3999999999999999 0 0.050000000000000003 -1.5707</pose>
          <topic>front_camera</topic>
          <update_rate>30</update_rate>
          <enable_metrics>false</enable_metrics>
          <camera>
            <pose>0 0 0 0 0 0</pose>
            <horizontal_fov>1.3962600000000001</horizontal_fov>
            <image>
              <width>800</width>
              <height>800</height>
              <format>RGB_INT8</format>
              <anti_aliasing>4</anti_aliasing>
            </image>
            <camera_info_topic>__default__</camera_info_topic>
            <trigger_topic></trigger_topic>
            <triggered>false</triggered>
            <clip>
              <near>0.02</near>
              <far>300</far>
            </clip>
            <save enabled='false'>
              <path>__default__</path>
            </save>
            <visibility_mask>4294967295</visibility_mask>
            <noise>
              <type>none</type>
              <mean>0</mean>
              <stddev>0</stddev>
            </noise>
            <distortion>
              <k1>0</k1>
              <k2>0</k2>
              <k3>0</k3>
              <p1>0</p1>
              <p2>0</p2>
              <center>0.5 0.5</center>
            </distortion>
            <lens>
              <type>stereographic</type>
              <scale_to_hfov>true</scale_to_hfov>
              <cutoff_angle>1.5707963267948966</cutoff_angle>
              <env_texture_size>256</env_texture_size>
            </lens>
            <optical_frame_id></optical_frame_id>
          </camera>
        </sensor>
        <sensor name='left_camera_sensor' type='camera'>
          <pose>1 -0.69999999999999996 1 0 0.050000000000000003 1</pose>
          <topic>left_camera</topic>
          <update_rate>30</update_rate>
          <enable_metrics>false</enable_metrics>
          <camera>
            <pose>0 0 0 0 0 0</pose>
            <horizontal_fov>1.3962600000000001</horizontal_fov>
            <image>
              <width>800</width>
              <height>800</height>
              <format>RGB_INT8</format>
              <anti_aliasing>4</anti_aliasing>
            </image>
            <camera_info_topic>__default__</camera_info_topic>
            <trigger_topic></trigger_topic>
            <triggered>false</triggered>
            <clip>
              <near>0.02</near>
              <far>300</far>
            </clip>
            <save enabled='false'>
              <path>__default__</path>
            </save>
            <visibility_mask>4294967295</visibility_mask>
            <noise>
              <type>none</type>
              <mean>0</mean>
              <stddev>0</stddev>
            </noise>
            <distortion>
              <k1>0</k1>
              <k2>0</k2>
              <k3>0</k3>
              <p1>0</p1>
              <p2>0</p2>
              <center>0.5 0.5</center>
            </distortion>
            <lens>
              <type>stereographic</type>
              <scale_to_hfov>true</scale_to_hfov>
              <cutoff_angle>1.5707963267948966</cutoff_angle>
              <env_texture_size>256</env_texture_size>
            </lens>
            <optical_frame_id></optical_frame_id>
          </camera>
        </sensor>
        <sensor name='right_camera_sensor' type='camera'>
          <pose>-1 -0.69999999999999996 1 0 0.050000000000000003 2.1415999999999999</pose>
          <topic>right_camera</topic>
          <update_rate>30</update_rate>
          <enable_metrics>false</enable_metrics>
          <camera>
            <pose>0 0 0 0 0 0</pose>
            <horizontal_fov>1.3962600000000001</horizontal_fov>
            <image>
              <width>800</width>
              <height>800</height>
              <format>RGB_INT8</format>
              <anti_aliasing>4</anti_aliasing>
            </image>
            <camera_info_topic>__default__</camera_info_topic>
            <trigger_topic></trigger_topic>
            <triggered>false</triggered>
            <clip>
              <near>0.02</near>
              <far>300</far>
            </clip>
            <save enabled='false'>
              <path>__default__</path>
            </save>
            <visibility_mask>4294967295</visibility_mask>
            <noise>
              <type>none</type>
              <mean>0</mean>
              <stddev>0</stddev>
            </noise>
            <distortion>
              <k1>0</k1>
              <k2>0</k2>
              <k3>0</k3>
              <p1>0</p1>
              <p2>0</p2>
              <center>0.5 0.5</center>
            </distortion>
            <lens>
              <type>stereographic</type>
              <scale_to_hfov>true</scale_to_hfov>
              <cutoff_angle>1.5707963267948966</cutoff_angle>
              <env_texture_size>256</env_texture_size>
            </lens>
            <optical_frame_id></optical_frame_id>
          </camera>
        </sensor>
        <pose>0 0 0 0 0 0</pose>
        <enable_wind>false</enable_wind>
      </link>
      <link name='steering_wheel'>
        <pose>0.35684764999258789 -0.62929564227295032 0.98739251043906506 -1.5191247929718121 0.43923232065545653 -0.90807703186383626</pose>
        <inertial>
          <mass>1</mass>
          <inertia>
            <ixx>0.14583299999999999</ixx>
            <ixy>0</ixy>
            <ixz>0</ixz>
            <iyy>0.14583299999999999</iyy>
            <iyz>0</iyz>
            <izz>0.125</izz>
          </inertia>
          <pose>0 0 0 0 0 0</pose>
        </inertial>
        <collision name='collision'>
          <geometry>
            <cylinder>
              <radius>0.178172</radius>
              <length>0.041845</length>
            </cylinder>
          </geometry>
          <surface>
            <contact>
              <ode>
                <min_depth>0.0030000000000000001</min_depth>
              </ode>
            </contact>
            <friction>
              <ode/>
            </friction>
            <bounce/>
          </surface>
        </collision>
        <visual name='visual'>
          <pose>0 0 0 1.302101 0 0</pose>
          <geometry>
            <mesh>
              <uri>https://fuel.ignitionrobotics.org/1.0/openrobotics/models/prius hybrid/2/files/meshes/Hybrid.obj</uri>
              <scale>0.01 0.01 0.01</scale>
              <submesh>
                <name>Steering_Wheel</name>
                <center>true</center>
              </submesh>
            </mesh>
          </geometry>
        </visual>
        <enable_wind>false</enable_wind>
      </link>
      <link name='front_left_wheel'>
        <pose>0.75999997405274655 -1.4100002351122498 0.30000000000000071 3.8284549736151974e-09 4.4933322446913256e-16 8.8541163290045771e-10</pose>
        <inertial>
          <mass>11</mass>
          <inertia>
            <ixx>0.58631237999999997</ixx>
            <ixy>0</ixy>
            <iyy>0.33552910000000002</iyy>
            <ixz>0</ixz>
            <iyz>0</iyz>
            <izz>0.33552910000000002</izz>
          </inertia>
          <pose>0 0 0 0 0 0</pose>
        </inertial>
        <visual name='visual'>
          <pose>0.040000000000000001 0 0 0 0 0</pose>
          <geometry>
            <mesh>
              <uri>https://fuel.ignitionrobotics.org/1.0/openrobotics/models/prius hybrid/2/files/meshes/Hybrid.obj</uri>
              <scale>0.01 0.01 0.01</scale>
              <submesh>
                <name>Wheel_Front_Left_</name>
                <center>true</center>
              </submesh>
            </mesh>
          </geometry>
        </visual>
        <collision name='collision'>
          <pose>0 0 0 0 1.5707963267948966 0</pose>
          <geometry>
            <sphere>
              <radius>0.31264999999999998</radius>
            </sphere>
          </geometry>
          <surface>
            <friction>
              <ode>
                <mu>0.90000000000000002</mu>
                <mu2>0.90000000000000002</mu2>
                <slip1>0</slip1>
                <slip2>0</slip2>
              </ode>
            </friction>
            <contact>
              <ode>
                <min_depth>0.001</min_depth>
                <kp>1000000000</kp>
              </ode>
            </contact>
            <bounce/>
          </surface>
        </collision>
        <enable_wind>false</enable_wind>
      </link>
      <link name='front_right_wheel'>
        <pose>-0.75999999999994827 -1.4100000000001387 0.30000000000000249 5.896448325264092e-10 -1.0703163198322174e-17 9.9999974967346361e-10</pose>
        <inertial>
          <mass>11</mass>
          <inertia>
            <ixx>0.58631237999999997</ixx>
            <ixy>0</ixy>
            <iyy>0.33552910000000002</iyy>
            <ixz>0</ixz>
            <iyz>0</iyz>
            <izz>0.33552910000000002</izz>
          </inertia>
          <pose>0 0 0 0 0 0</pose>
        </inertial>
        <visual name='visual'>
          <pose>-0.040000000000000001 0 0 0 0 0</pose>
          <pose>0 0 0 0 0 0</pose>
          <geometry>
            <mesh>
              <uri>https://fuel.ignitionrobotics.org/1.0/openrobotics/models/prius hybrid/2/files/meshes/Hybrid.obj</uri>
              <scale>0.01 0.01 0.01</scale>
              <submesh>
                <name>Wheel_Front_Right</name>
                <center>true</center>
              </submesh>
            </mesh>
          </geometry>
        </visual>
        <collision name='collision'>
          <pose>0 0 0 0 1.5707963267948966 0</pose>
          <geometry>
            <sphere>
              <radius>0.31264999999999998</radius>
            </sphere>
          </geometry>
          <surface>
            <friction>
              <ode>
                <mu>0.90000000000000002</mu>
                <mu2>0.90000000000000002</mu2>
                <slip1>0</slip1>
                <slip2>0</slip2>
              </ode>
            </friction>
            <contact>
              <ode>
                <min_depth>0.001</min_depth>
                <kp>1000000000</kp>
              </ode>
            </contact>
            <bounce/>
          </surface>
        </collision>
        <enable_wind>false</enable_wind>
      </link>
      <link name='rear_left_wheel'>
        <pose>0.78599998126723847 1.4499998280853106 0.30000000007144578 3.497636556254103e-09 -9.0904736716493117e-11 -8.3784979113757644e-11</pose>
        <inertial>
          <mass>11</mass>
          <inertia>
            <ixx>0.58631237999999997</ixx>
            <ixy>0</ixy>
            <iyy>0.33552910000000002</iyy>
            <ixz>0</ixz>
            <iyz>0</iyz>
            <izz>0.33552910000000002</izz>
          </inertia>
          <pose>0 0 0 0 0 0</pose>
        </inertial>
        <visual name='visual'>
          <pose>0.040000000000000001 0 0 0 0 0</pose>
          <geometry>
            <mesh>
              <uri>https://fuel.ignitionrobotics.org/1.0/openrobotics/models/prius hybrid/2/files/meshes/Hybrid.obj</uri>
              <scale>0.01 0.01 0.01</scale>
              <submesh>
                <name>Wheel_Front_Left_</name>
                <center>true</center>
              </submesh>
            </mesh>
          </geometry>
        </visual>
        <collision name='collision'>
          <pose>0 0 0 0 1.5707963267948966 0</pose>
          <geometry>
            <sphere>
              <radius>0.31264999999999998</radius>
            </sphere>
          </geometry>
          <surface>
            <friction>
              <ode>
                <mu>1.1000000000000001</mu>
                <mu2>1.1000000000000001</mu2>
                <slip1>0</slip1>
                <slip2>0</slip2>
              </ode>
            </friction>
            <contact>
              <ode>
                <min_depth>0.001</min_depth>
                <kp>1000000000</kp>
              </ode>
            </contact>
            <bounce/>
          </surface>
        </collision>
        <enable_wind>false</enable_wind>
      </link>
      <link name='rear_right_wheel'>
        <pose>-0.78600006975081271 1.4499993603732264 0.29999999992853077 4.2395545148845955e-10 -9.090588691854548e-11 -3.1199931529152999e-10</pose>
        <inertial>
          <mass>11</mass>
          <inertia>
            <ixx>0.58631237999999997</ixx>
            <ixy>0</ixy>
            <iyy>0.33552910000000002</iyy>
            <ixz>0</ixz>
            <iyz>0</iyz>
            <izz>0.33552910000000002</izz>
          </inertia>
          <pose>0 0 0 0 0 0</pose>
        </inertial>
        <visual name='visual'>
          <pose>-0.040000000000000001 0 0 0 0 0</pose>
          <geometry>
            <mesh>
              <uri>https://fuel.ignitionrobotics.org/1.0/openrobotics/models/prius hybrid/2/files/meshes/Hybrid.obj</uri>
              <scale>0.01 0.01 0.01</scale>
              <submesh>
                <name>Wheel_Front_Right</name>
                <center>true</center>
              </submesh>
            </mesh>
          </geometry>
        </visual>
        <collision name='collision'>
          <pose>0 0 0 0 1.5707963267948966 0</pose>
          <geometry>
            <sphere>
              <radius>0.31264999999999998</radius>
            </sphere>
          </geometry>
          <surface>
            <friction>
              <ode>
                <mu>1.1000000000000001</mu>
                <mu2>1.1000000000000001</mu2>
                <slip1>0</slip1>
                <slip2>0</slip2>
              </ode>
            </friction>
            <contact>
              <ode>
                <min_depth>0.001</min_depth>
                <kp>1000000000</kp>
              </ode>
            </contact>
            <bounce/>
          </surface>
        </collision>
        <enable_wind>false</enable_wind>
      </link>
      <link name='rear_axle'>
        <pose>1.4210854715202004e-14 1.4499999999999318 0.30000000000000249 1.1709383457797014e-17 -9.0908469987938112e-11 1.1102230246198341e-16</pose>
        <inertial>
          <mass>30</mass>
          <inertia>
            <ixx>0.084374999999999992</ixx>
            <ixy>0</ixy>
            <iyy>4.64581</iyy>
            <ixz>0</ixz>
            <iyz>0</iyz>
            <izz>4.64581</izz>
          </inertia>
          <pose>0 0 0 0 0 0</pose>
        </inertial>
        <visual name='visual'>
          <pose>0 0 0 0 1.5707963267948966 0</pose>
          <geometry>
            <cylinder>
              <length>1.357</length>
              <radius>0.074999999999999997</radius>
            </cylinder>
          </geometry>
          <material>
            <script>
              <name>Gazebo/Grey</name>
              <uri>file://media/materials/scripts/gazebo.material</uri>
            </script>
          </material>
        </visual>
        <enable_wind>false</enable_wind>
      </link>
      <joint name='rear_axle_joint' type='revolute'>
        <child>rear_axle</child>
        <parent>chassis</parent>
        <axis>
          <xyz>0 1 0</xyz>
          <limit>
            <lower>-0.050890585241730277</lower>
            <upper>0.050890585241730277</upper>
            <effort>inf</effort>
            <velocity>inf</velocity>
            <stiffness>100000000</stiffness>
            <dissipation>1</dissipation>
          </limit>
          <dynamics>
            <spring_reference>0</spring_reference>
            <spring_stiffness>0</spring_stiffness>
            <damping>2000</damping>
            <friction>0</friction>
          </dynamics>
        </axis>
        <pose>0 0 0 0 0 0</pose>
      </joint>
      <joint name='rear_left_wheel_joint' type='revolute'>
        <child>rear_left_wheel</child>
        <parent>rear_axle</parent>
        <axis>
          <xyz>1 0 0</xyz>
          <limit>
            <lower>-inf</lower>
            <upper>inf</upper>
            <effort>inf</effort>
            <velocity>inf</velocity>
            <stiffness>100000000</stiffness>
            <dissipation>1</dissipation>
          </limit>
          <dynamics>
            <spring_reference>0</spring_reference>
            <spring_stiffness>0</spring_stiffness>
            <damping>0</damping>
            <friction>12.031606150200002</friction>
          </dynamics>
        </axis>
        <pose>0 0 0 0 0 0</pose>
      </joint>
      <joint name='rear_right_wheel_joint' type='revolute'>
        <child>rear_right_wheel</child>
        <parent>rear_axle</parent>
        <axis>
          <xyz>1 0 0</xyz>
          <limit>
            <lower>-inf</lower>
            <upper>inf</upper>
            <effort>inf</effort>
            <velocity>inf</velocity>
            <stiffness>100000000</stiffness>
            <dissipation>1</dissipation>
          </limit>
          <dynamics>
            <spring_reference>0</spring_reference>
            <spring_stiffness>0</spring_stiffness>
            <damping>0</damping>
            <friction>12.031606150200002</friction>
          </dynamics>
        </axis>
        <pose>0 0 0 0 0 0</pose>
      </joint>
      <joint name='steering_joint' type='revolute'>
        <pose>-0.002 -2.2204499999999999e-16 1.11022e-16 0 0 0</pose>
        <parent>chassis</parent>
        <child>steering_wheel</child>
        <axis>
          <xyz>0 0.96409540580664155 0.26555611177776933</xyz>
          <limit>
            <lower>-7.8499999999999996</lower>
            <upper>7.8499999999999996</upper>
            <effort>inf</effort>
            <velocity>inf</velocity>
            <stiffness>100000000</stiffness>
            <dissipation>1</dissipation>
          </limit>
          <dynamics>
            <spring_reference>0</spring_reference>
            <spring_stiffness>0</spring_stiffness>
            <damping>1</damping>
            <friction>0</friction>
          </dynamics>
        </axis>
        <physics>
          <ode>
            <cfm_damping>true</cfm_damping>
          </ode>
        </physics>
      </joint>
      <link name='front_left_wheel_steering_link'>
        <pose>0.75999997405274655 -1.4100002351122498 0.30000000000000071 -2.2694519872446807e-15 4.5623227518660012e-16 8.8541196596736406e-10</pose>
        <inertial>
          <mass>0.5</mass>
          <inertia>
            <ixx>0.015299999999999999</ixx>
            <iyy>0.025000000000000001</iyy>
            <izz>0.015299999999999999</izz>
            <ixy>0</ixy>
            <ixz>0</ixz>
            <iyz>0</iyz>
          </inertia>
          <pose>0 0 0 0 0 0</pose>
        </inertial>
        <enable_wind>false</enable_wind>
      </link>
      <link name='front_right_wheel_steering_link'>
        <pose>-0.75999999999994827 -1.4100000000001387 0.30000000000000249 5.6378512934551766e-18 -6.9388939067261535e-18 9.9999986069576607e-10</pose>
        <inertial>
          <mass>0.5</mass>
          <inertia>
            <ixx>0.015299999999999999</ixx>
            <iyy>0.025000000000000001</iyy>
            <izz>0.015299999999999999</izz>
            <ixy>0</ixy>
            <ixz>0</ixz>
            <iyz>0</iyz>
          </inertia>
          <pose>0 0 0 0 0 0</pose>
        </inertial>
        <enable_wind>false</enable_wind>
      </link>
      <joint name='front_left_wheel_steering_joint' type='revolute'>
        <child>front_left_wheel_steering_link</child>
        <parent>chassis</parent>
        <axis>
          <xyz>0 0 1</xyz>
          <limit>
            <lower>-0.87270000000000003</lower>
            <upper>0.87270000000000003</upper>
            <effort>1000000</effort>
            <velocity>inf</velocity>
            <stiffness>100000000</stiffness>
            <dissipation>1</dissipation>
          </limit>
          <dynamics>
            <spring_reference>0</spring_reference>
            <spring_stiffness>0</spring_stiffness>
            <damping>0</damping>
            <friction>0</friction>
          </dynamics>
        </axis>
        <pose>0 0 0 0 0 0</pose>
      </joint>
      <joint name='front_right_wheel_steering_joint' type='revolute'>
        <parent>chassis</parent>
        <child>front_right_wheel_steering_link</child>
        <axis>
          <xyz>0 0 1</xyz>
          <limit>
            <lower>-0.87270000000000003</lower>
            <upper>0.87270000000000003</upper>
            <effort>1000000</effort>
            <velocity>inf</velocity>
            <stiffness>100000000</stiffness>
            <dissipation>1</dissipation>
          </limit>
          <dynamics>
            <spring_reference>0</spring_reference>
            <spring_stiffness>0</spring_stiffness>
            <damping>0</damping>
            <friction>0</friction>
          </dynamics>
        </axis>
        <pose>0 0 0 0 0 0</pose>
      </joint>
      <joint name='front_left_wheel_joint' type='revolute'>
        <parent>front_left_wheel_steering_link</parent>
        <child>front_left_wheel</child>
        <axis>
          <xyz>1 0 0</xyz>
          <limit>
            <lower>-1.7976900000000001e+308</lower>
            <upper>1.7976900000000001e+308</upper>
            <effort>inf</effort>
            <velocity>inf</velocity>
            <stiffness>100000000</stiffness>
            <dissipation>1</dissipation>
          </limit>
          <dynamics>
            <spring_reference>0</spring_reference>
            <spring_stiffness>0</spring_stiffness>
            <damping>0</damping>
            <friction>18.047409225300001</friction>
          </dynamics>
        </axis>
        <pose>0 0 0 0 0 0</pose>
      </joint>
      <joint name='front_right_wheel_joint' type='revolute'>
        <parent>front_right_wheel_steering_link</parent>
        <child>front_right_wheel</child>
        <axis>
          <xyz>1 0 0</xyz>
          <limit>
            <lower>-1.7976900000000001e+308</lower>
            <upper>1.7976900000000001e+308</upper>
            <effort>inf</effort>
            <velocity>inf</velocity>
            <stiffness>100000000</stiffness>
            <dissipation>1</dissipation>
          </limit>
          <dynamics>
            <spring_reference>0</spring_reference>
            <spring_stiffness>0</spring_stiffness>
            <damping>0</damping>
            <friction>18.047409225300001</friction>
          </dynamics>
        </axis>
        <pose>0 0 0 0 0 0</pose>
      </joint>
      <plugin name='ignition::gazebo::systems::AckermannSteering' filename='ignition-gazebo-ackermann-steering-system'>
        <topic>/cmd_vel</topic>
        <left_joint>front_left_wheel_joint</left_joint>
        <left_joint>rear_left_wheel_joint</left_joint>
        <right_joint>front_right_wheel_joint</right_joint>
        <right_joint>rear_right_wheel_joint</right_joint>
        <left_steering_joint>front_left_wheel_steering_joint</left_steering_joint>
        <right_steering_joint>front_right_wheel_steering_joint</right_steering_joint>
        <kingpin_width>1.0</kingpin_width>
        <steering_limit>0.5</steering_limit>
        <wheel_base>1.0</wheel_base>
        <wheel_separation>1.572</wheel_separation>
        <wheel_radius>0.31265</wheel_radius>
        <min_velocity>-10</min_velocity>
        <max_velocity>100</max_velocity>
        <min_acceleration>-30</min_acceleration>
        <max_acceleration>30</max_acceleration>
      </plugin>
      <static>false</static>
      <self_collide>false</self_collide>
    </model>
  </world>
</sdf>
